Traceback (most recent call last):
  File "C:\Users\vanisa\AppData\Roaming\Python\Python313\site-packages\jupyter_core\utils\__init__.py", line 154, in wrapped
    asyncio.get_running_loop()
    ~~~~~~~~~~~~~~~~~~~~~~~~^^
RuntimeError: no running event loop

During handling of the above exception, another exception occurred:

Traceback (most recent call last):
  File "C:\Users\vanisa\AppData\Local\Programs\Python\Python313\Lib\site-packages\jupyter_cache\executors\utils.py", line 58, in single_nb_execution
    executenb(
    ~~~~~~~~~^
        nb,
        ^^^
    ...<4 lines>...
        **kwargs,
        ^^^^^^^^^
    )
    ^
  File "C:\Users\vanisa\AppData\Local\Programs\Python\Python313\Lib\site-packages\nbclient\client.py", line 1305, in execute
    return NotebookClient(nb=nb, resources=resources, km=km, **kwargs).execute()
           ~~~~~~~~~~~~~~~~~~~~~~~~~~~~~~~~~~~~~~~~~~~~~~~~~~~~~~~~~~~~~~~~~~~^^
  File "C:\Users\vanisa\AppData\Roaming\Python\Python313\site-packages\jupyter_core\utils\__init__.py", line 158, in wrapped
    return loop.run_until_complete(inner)
           ~~~~~~~~~~~~~~~~~~~~~~~^^^^^^^
  File "C:\Users\vanisa\AppData\Local\Programs\Python\Python313\Lib\asyncio\base_events.py", line 725, in run_until_complete
    return future.result()
           ~~~~~~~~~~~~~^^
  File "C:\Users\vanisa\AppData\Local\Programs\Python\Python313\Lib\site-packages\nbclient\client.py", line 705, in async_execute
    await self.async_execute_cell(
        cell, index, execution_count=self.code_cells_executed + 1
    )
  File "C:\Users\vanisa\AppData\Local\Programs\Python\Python313\Lib\site-packages\nbclient\client.py", line 1058, in async_execute_cell
    await self._check_raise_for_error(cell, cell_index, exec_reply)
  File "C:\Users\vanisa\AppData\Local\Programs\Python\Python313\Lib\site-packages\nbclient\client.py", line 914, in _check_raise_for_error
    raise CellExecutionError.from_cell_and_msg(cell, exec_reply_content)
nbclient.exceptions.CellExecutionError: An error occurred while executing the following cell:
------------------
import pandas as pd
import pymysql
import psycopg2

mysql_conn = pymysql.connect(
    host="localhost",
    user="root",
    password="sk25",   
    database="db_iris",
    port=3306
)

petal = pd.read_sql("SELECT * FROM petal", mysql_conn)

pg_conn = psycopg2.connect(
    host="localhost",
    user="postgres",  
    password="sk25_",
    database="iris_db",
    port=5432
)

sepal = pd.read_sql("SELECT * FROM sepal", pg_conn)

iris = pd.concat([petal, sepal], axis=1)

dataset = iris
------------------


[31m---------------------------------------------------------------------------[39m
[31mModuleNotFoundError[39m                       Traceback (most recent call last)
[36mCell[39m[36m [39m[32mIn[4][39m[32m, line 2[39m
[32m      1[39m [38;5;28;01mimport[39;00m[38;5;250m [39m[34;01mpandas[39;00m[38;5;250m [39m[38;5;28;01mas[39;00m[38;5;250m [39m[34;01mpd[39;00m
[32m----> [39m[32m2[39m [38;5;28;01mimport[39;00m[38;5;250m [39m[34;01mpymysql[39;00m
[32m      3[39m [38;5;28;01mimport[39;00m[38;5;250m [39m[34;01mpsycopg2[39;00m
[32m      5[39m mysql_conn = pymysql.connect(
[32m      6[39m     host=[33m"[39m[33mlocalhost[39m[33m"[39m,
[32m      7[39m     user=[33m"[39m[33mroot[39m[33m"[39m,
[32m   (...)[39m[32m     10[39m     port=[32m3306[39m
[32m     11[39m )

[31mModuleNotFoundError[39m: No module named 'pymysql'

